2025-09-01 02:36:47|ERROR   |root                            |Error trying to get announcements from Github. Connection Error.|'Traceback (most recent call last):\n  File "/app/bazarr/bin/bazarr/../libs/urllib3/connection.py", line 199, in _new_conn\n    sock = connection.create_connection(\n           ^^^^^^^^^^^^^^^^^^^^^^^^^^^^^\n  File "/app/bazarr/bin/bazarr/../custom_libs/subliminal_patch/http.py", line 325, in patched_create_connection\n    return _orig_create_connection(address, *args, **kwargs)\n           ^^^^^^^^^^^^^^^^^^^^^^^^^^^^^^^^^^^^^^^^^^^^^^^^^\n  File "/app/bazarr/bin/bazarr/../libs/urllib3/util/connection.py", line 60, in create_connection\n    for res in socket.getaddrinfo(host, port, family, socket.SOCK_STREAM):\n               ^^^^^^^^^^^^^^^^^^^^^^^^^^^^^^^^^^^^^^^^^^^^^^^^^^^^^^^^^^\n  File "/usr/lib/python3.12/socket.py", line 978, in getaddrinfo\n    for res in _socket.getaddrinfo(host, port, family, type, proto, flags):\n               ^^^^^^^^^^^^^^^^^^^^^^^^^^^^^^^^^^^^^^^^^^^^^^^^^^^^^^^^^^^\nsocket.gaierror: [Errno -3] Try again\n\nThe above exception was the direct cause of the following exception:\n\nTraceback (most recent call last):\n  File "/app/bazarr/bin/bazarr/../libs/urllib3/connectionpool.py", line 789, in urlopen\n    response = self._make_request(\n               ^^^^^^^^^^^^^^^^^^^\n  File "/app/bazarr/bin/bazarr/../libs/urllib3/connectionpool.py", line 490, in _make_request\n    raise new_e\n  File "/app/bazarr/bin/bazarr/../libs/urllib3/connectionpool.py", line 466, in _make_request\n    self._validate_conn(conn)\n  File "/app/bazarr/bin/bazarr/../libs/urllib3/connectionpool.py", line 1095, in _validate_conn\n    conn.connect()\n  File "/app/bazarr/bin/bazarr/../libs/urllib3/connection.py", line 693, in connect\n    self.sock = sock = self._new_conn()\n                       ^^^^^^^^^^^^^^^^\n  File "/app/bazarr/bin/bazarr/../libs/urllib3/connection.py", line 206, in _new_conn\n    raise NameResolutionError(self.host, self, e) from e\nurllib3.exceptions.NameResolutionError: <urllib3.connection.HTTPSConnection object at 0xffff82150b60>: Failed to resolve \'raw.githubusercontent.com\' ([Errno -3] Try again)\n\nThe above exception was the direct cause of the following exception:\n\nTraceback (most recent call last):\n  File "/app/bazarr/bin/bazarr/../libs/requests/adapters.py", line 667, in send\n    resp = conn.urlopen(\n           ^^^^^^^^^^^^^\n  File "/app/bazarr/bin/bazarr/../libs/urllib3/connectionpool.py", line 843, in urlopen\n    retries = retries.increment(\n              ^^^^^^^^^^^^^^^^^^\n  File "/app/bazarr/bin/bazarr/../libs/urllib3/util/retry.py", line 519, in increment\n    raise MaxRetryError(_pool, url, reason) from reason  # type: ignore[arg-type]\n    ^^^^^^^^^^^^^^^^^^^^^^^^^^^^^^^^^^^^^^^^^^^^^^^^^^^\nurllib3.exceptions.MaxRetryError: HTTPSConnectionPool(host=\'raw.githubusercontent.com\', port=443): Max retries exceeded with url: /morpheus65535/bazarr-binaries/master/announcements.json (Caused by NameResolutionError("<urllib3.connection.HTTPSConnection object at 0xffff82150b60>: Failed to resolve \'raw.githubusercontent.com\' ([Errno -3] Try again)"))\n\nDuring handling of the above exception, another exception occurred:\n\nTraceback (most recent call last):\n  File "/app/bazarr/bin/bazarr/app/announcements.py", line 53, in get_announcements_to_file\n    r = requests.get("https://raw.githubusercontent.com/morpheus65535/bazarr-binaries/master/announcements.json",\n        ^^^^^^^^^^^^^^^^^^^^^^^^^^^^^^^^^^^^^^^^^^^^^^^^^^^^^^^^^^^^^^^^^^^^^^^^^^^^^^^^^^^^^^^^^^^^^^^^^^^^^^^^^\n  File "/app/bazarr/bin/bazarr/../libs/requests/api.py", line 73, in get\n    return request("get", url, params=params, **kwargs)\n           ^^^^^^^^^^^^^^^^^^^^^^^^^^^^^^^^^^^^^^^^^^^^\n  File "/app/bazarr/bin/bazarr/../libs/requests/api.py", line 59, in request\n    return session.request(method=method, url=url, **kwargs)\n           ^^^^^^^^^^^^^^^^^^^^^^^^^^^^^^^^^^^^^^^^^^^^^^^^^\n  File "/app/bazarr/bin/bazarr/../libs/requests/sessions.py", line 589, in request\n    resp = self.send(prep, **send_kwargs)\n           ^^^^^^^^^^^^^^^^^^^^^^^^^^^^^^\n  File "/app/bazarr/bin/bazarr/../libs/requests/sessions.py", line 703, in send\n    r = adapter.send(request, **kwargs)\n        ^^^^^^^^^^^^^^^^^^^^^^^^^^^^^^^\n  File "/app/bazarr/bin/bazarr/../libs/requests/adapters.py", line 700, in send\n    raise ConnectionError(e, request=request)\nrequests.exceptions.ConnectionError: HTTPSConnectionPool(host=\'raw.githubusercontent.com\', port=443): Max retries exceeded with url: /morpheus65535/bazarr-binaries/master/announcements.json (Caused by NameResolutionError("<urllib3.connection.HTTPSConnection object at 0xffff82150b60>: Failed to resolve \'raw.githubusercontent.com\' ([Errno -3] Try again)"))'|
2025-09-01 02:43:24|ERROR   |root                            |Error trying to get releases from Github. Connection Error.|'Traceback (most recent call last):\n  File "/app/bazarr/bin/bazarr/../libs/urllib3/connection.py", line 199, in _new_conn\n    sock = connection.create_connection(\n           ^^^^^^^^^^^^^^^^^^^^^^^^^^^^^\n  File "/app/bazarr/bin/bazarr/../custom_libs/subliminal_patch/http.py", line 325, in patched_create_connection\n    return _orig_create_connection(address, *args, **kwargs)\n           ^^^^^^^^^^^^^^^^^^^^^^^^^^^^^^^^^^^^^^^^^^^^^^^^^\n  File "/app/bazarr/bin/bazarr/../libs/urllib3/util/connection.py", line 60, in create_connection\n    for res in socket.getaddrinfo(host, port, family, socket.SOCK_STREAM):\n               ^^^^^^^^^^^^^^^^^^^^^^^^^^^^^^^^^^^^^^^^^^^^^^^^^^^^^^^^^^\n  File "/usr/lib/python3.12/socket.py", line 978, in getaddrinfo\n    for res in _socket.getaddrinfo(host, port, family, type, proto, flags):\n               ^^^^^^^^^^^^^^^^^^^^^^^^^^^^^^^^^^^^^^^^^^^^^^^^^^^^^^^^^^^\nsocket.gaierror: [Errno -3] Try again\n\nThe above exception was the direct cause of the following exception:\n\nTraceback (most recent call last):\n  File "/app/bazarr/bin/bazarr/../libs/urllib3/connectionpool.py", line 789, in urlopen\n    response = self._make_request(\n               ^^^^^^^^^^^^^^^^^^^\n  File "/app/bazarr/bin/bazarr/../libs/urllib3/connectionpool.py", line 490, in _make_request\n    raise new_e\n  File "/app/bazarr/bin/bazarr/../libs/urllib3/connectionpool.py", line 466, in _make_request\n    self._validate_conn(conn)\n  File "/app/bazarr/bin/bazarr/../libs/urllib3/connectionpool.py", line 1095, in _validate_conn\n    conn.connect()\n  File "/app/bazarr/bin/bazarr/../libs/urllib3/connection.py", line 693, in connect\n    self.sock = sock = self._new_conn()\n                       ^^^^^^^^^^^^^^^^\n  File "/app/bazarr/bin/bazarr/../libs/urllib3/connection.py", line 206, in _new_conn\n    raise NameResolutionError(self.host, self, e) from e\nurllib3.exceptions.NameResolutionError: <urllib3.connection.HTTPSConnection object at 0xffff81d142c0>: Failed to resolve \'api.github.com\' ([Errno -3] Try again)\n\nThe above exception was the direct cause of the following exception:\n\nTraceback (most recent call last):\n  File "/app/bazarr/bin/bazarr/../libs/requests/adapters.py", line 667, in send\n    resp = conn.urlopen(\n           ^^^^^^^^^^^^^\n  File "/app/bazarr/bin/bazarr/../libs/urllib3/connectionpool.py", line 843, in urlopen\n    retries = retries.increment(\n              ^^^^^^^^^^^^^^^^^^\n  File "/app/bazarr/bin/bazarr/../libs/urllib3/util/retry.py", line 519, in increment\n    raise MaxRetryError(_pool, url, reason) from reason  # type: ignore[arg-type]\n    ^^^^^^^^^^^^^^^^^^^^^^^^^^^^^^^^^^^^^^^^^^^^^^^^^^^\nurllib3.exceptions.MaxRetryError: HTTPSConnectionPool(host=\'api.github.com\', port=443): Max retries exceeded with url: /repos/morpheus65535/Bazarr/releases?per_page=100 (Caused by NameResolutionError("<urllib3.connection.HTTPSConnection object at 0xffff81d142c0>: Failed to resolve \'api.github.com\' ([Errno -3] Try again)"))\n\nDuring handling of the above exception, another exception occurred:\n\nTraceback (most recent call last):\n  File "/app/bazarr/bin/bazarr/app/check_update.py", line 28, in check_releases\n    r = requests.get(url_releases, allow_redirects=True, timeout=15)\n        ^^^^^^^^^^^^^^^^^^^^^^^^^^^^^^^^^^^^^^^^^^^^^^^^^^^^^^^^^^^^\n  File "/app/bazarr/bin/bazarr/../libs/requests/api.py", line 73, in get\n    return request("get", url, params=params, **kwargs)\n           ^^^^^^^^^^^^^^^^^^^^^^^^^^^^^^^^^^^^^^^^^^^^\n  File "/app/bazarr/bin/bazarr/../libs/requests/api.py", line 59, in request\n    return session.request(method=method, url=url, **kwargs)\n           ^^^^^^^^^^^^^^^^^^^^^^^^^^^^^^^^^^^^^^^^^^^^^^^^^\n  File "/app/bazarr/bin/bazarr/../libs/requests/sessions.py", line 589, in request\n    resp = self.send(prep, **send_kwargs)\n           ^^^^^^^^^^^^^^^^^^^^^^^^^^^^^^\n  File "/app/bazarr/bin/bazarr/../libs/requests/sessions.py", line 703, in send\n    r = adapter.send(request, **kwargs)\n        ^^^^^^^^^^^^^^^^^^^^^^^^^^^^^^^\n  File "/app/bazarr/bin/bazarr/../libs/requests/adapters.py", line 700, in send\n    raise ConnectionError(e, request=request)\nrequests.exceptions.ConnectionError: HTTPSConnectionPool(host=\'api.github.com\', port=443): Max retries exceeded with url: /repos/morpheus65535/Bazarr/releases?per_page=100 (Caused by NameResolutionError("<urllib3.connection.HTTPSConnection object at 0xffff81d142c0>: Failed to resolve \'api.github.com\' ([Errno -3] Try again)"))'|
2025-09-01 02:43:41|INFO    |root                            |BAZARR Finished searching for missing Series Subtitles. Check History for more information.|
2025-09-01 03:00:02|INFO    |root                            |BAZARR Finished searching for missing Movies Subtitles. Check History for more information.|
2025-09-01 04:00:00|INFO    |root                            |BAZARR All existing episode subtitles indexed from disk.|
2025-09-01 04:00:00|INFO    |root                            |BAZARR All existing movie subtitles indexed from disk.|
2025-09-01 05:43:24|ERROR   |root                            |Error trying to get releases from Github. Connection Error.|'Traceback (most recent call last):\n  File "/app/bazarr/bin/bazarr/../libs/urllib3/connection.py", line 199, in _new_conn\n    sock = connection.create_connection(\n           ^^^^^^^^^^^^^^^^^^^^^^^^^^^^^\n  File "/app/bazarr/bin/bazarr/../custom_libs/subliminal_patch/http.py", line 325, in patched_create_connection\n    return _orig_create_connection(address, *args, **kwargs)\n           ^^^^^^^^^^^^^^^^^^^^^^^^^^^^^^^^^^^^^^^^^^^^^^^^^\n  File "/app/bazarr/bin/bazarr/../libs/urllib3/util/connection.py", line 60, in create_connection\n    for res in socket.getaddrinfo(host, port, family, socket.SOCK_STREAM):\n               ^^^^^^^^^^^^^^^^^^^^^^^^^^^^^^^^^^^^^^^^^^^^^^^^^^^^^^^^^^\n  File "/usr/lib/python3.12/socket.py", line 978, in getaddrinfo\n    for res in _socket.getaddrinfo(host, port, family, type, proto, flags):\n               ^^^^^^^^^^^^^^^^^^^^^^^^^^^^^^^^^^^^^^^^^^^^^^^^^^^^^^^^^^^\nsocket.gaierror: [Errno -3] Try again\n\nThe above exception was the direct cause of the following exception:\n\nTraceback (most recent call last):\n  File "/app/bazarr/bin/bazarr/../libs/urllib3/connectionpool.py", line 789, in urlopen\n    response = self._make_request(\n               ^^^^^^^^^^^^^^^^^^^\n  File "/app/bazarr/bin/bazarr/../libs/urllib3/connectionpool.py", line 490, in _make_request\n    raise new_e\n  File "/app/bazarr/bin/bazarr/../libs/urllib3/connectionpool.py", line 466, in _make_request\n    self._validate_conn(conn)\n  File "/app/bazarr/bin/bazarr/../libs/urllib3/connectionpool.py", line 1095, in _validate_conn\n    conn.connect()\n  File "/app/bazarr/bin/bazarr/../libs/urllib3/connection.py", line 693, in connect\n    self.sock = sock = self._new_conn()\n                       ^^^^^^^^^^^^^^^^\n  File "/app/bazarr/bin/bazarr/../libs/urllib3/connection.py", line 206, in _new_conn\n    raise NameResolutionError(self.host, self, e) from e\nurllib3.exceptions.NameResolutionError: <urllib3.connection.HTTPSConnection object at 0xffff8259ff80>: Failed to resolve \'api.github.com\' ([Errno -3] Try again)\n\nThe above exception was the direct cause of the following exception:\n\nTraceback (most recent call last):\n  File "/app/bazarr/bin/bazarr/../libs/requests/adapters.py", line 667, in send\n    resp = conn.urlopen(\n           ^^^^^^^^^^^^^\n  File "/app/bazarr/bin/bazarr/../libs/urllib3/connectionpool.py", line 843, in urlopen\n    retries = retries.increment(\n              ^^^^^^^^^^^^^^^^^^\n  File "/app/bazarr/bin/bazarr/../libs/urllib3/util/retry.py", line 519, in increment\n    raise MaxRetryError(_pool, url, reason) from reason  # type: ignore[arg-type]\n    ^^^^^^^^^^^^^^^^^^^^^^^^^^^^^^^^^^^^^^^^^^^^^^^^^^^\nurllib3.exceptions.MaxRetryError: HTTPSConnectionPool(host=\'api.github.com\', port=443): Max retries exceeded with url: /repos/morpheus65535/Bazarr/releases?per_page=100 (Caused by NameResolutionError("<urllib3.connection.HTTPSConnection object at 0xffff8259ff80>: Failed to resolve \'api.github.com\' ([Errno -3] Try again)"))\n\nDuring handling of the above exception, another exception occurred:\n\nTraceback (most recent call last):\n  File "/app/bazarr/bin/bazarr/app/check_update.py", line 28, in check_releases\n    r = requests.get(url_releases, allow_redirects=True, timeout=15)\n        ^^^^^^^^^^^^^^^^^^^^^^^^^^^^^^^^^^^^^^^^^^^^^^^^^^^^^^^^^^^^\n  File "/app/bazarr/bin/bazarr/../libs/requests/api.py", line 73, in get\n    return request("get", url, params=params, **kwargs)\n           ^^^^^^^^^^^^^^^^^^^^^^^^^^^^^^^^^^^^^^^^^^^^\n  File "/app/bazarr/bin/bazarr/../libs/requests/api.py", line 59, in request\n    return session.request(method=method, url=url, **kwargs)\n           ^^^^^^^^^^^^^^^^^^^^^^^^^^^^^^^^^^^^^^^^^^^^^^^^^\n  File "/app/bazarr/bin/bazarr/../libs/requests/sessions.py", line 589, in request\n    resp = self.send(prep, **send_kwargs)\n           ^^^^^^^^^^^^^^^^^^^^^^^^^^^^^^\n  File "/app/bazarr/bin/bazarr/../libs/requests/sessions.py", line 703, in send\n    r = adapter.send(request, **kwargs)\n        ^^^^^^^^^^^^^^^^^^^^^^^^^^^^^^^\n  File "/app/bazarr/bin/bazarr/../libs/requests/adapters.py", line 700, in send\n    raise ConnectionError(e, request=request)\nrequests.exceptions.ConnectionError: HTTPSConnectionPool(host=\'api.github.com\', port=443): Max retries exceeded with url: /repos/morpheus65535/Bazarr/releases?per_page=100 (Caused by NameResolutionError("<urllib3.connection.HTTPSConnection object at 0xffff8259ff80>: Failed to resolve \'api.github.com\' ([Errno -3] Try again)"))'|
2025-09-01 06:19:41|INFO    |root                            |BAZARR Finished searching for Subtitles to upgrade. Check History for more information.|
2025-09-01 08:36:47|ERROR   |root                            |Error trying to get announcements from Github. Connection Error.|'Traceback (most recent call last):\n  File "/app/bazarr/bin/bazarr/../libs/urllib3/connection.py", line 199, in _new_conn\n    sock = connection.create_connection(\n           ^^^^^^^^^^^^^^^^^^^^^^^^^^^^^\n  File "/app/bazarr/bin/bazarr/../custom_libs/subliminal_patch/http.py", line 325, in patched_create_connection\n    return _orig_create_connection(address, *args, **kwargs)\n           ^^^^^^^^^^^^^^^^^^^^^^^^^^^^^^^^^^^^^^^^^^^^^^^^^\n  File "/app/bazarr/bin/bazarr/../libs/urllib3/util/connection.py", line 60, in create_connection\n    for res in socket.getaddrinfo(host, port, family, socket.SOCK_STREAM):\n               ^^^^^^^^^^^^^^^^^^^^^^^^^^^^^^^^^^^^^^^^^^^^^^^^^^^^^^^^^^\n  File "/usr/lib/python3.12/socket.py", line 978, in getaddrinfo\n    for res in _socket.getaddrinfo(host, port, family, type, proto, flags):\n               ^^^^^^^^^^^^^^^^^^^^^^^^^^^^^^^^^^^^^^^^^^^^^^^^^^^^^^^^^^^\nsocket.gaierror: [Errno -3] Try again\n\nThe above exception was the direct cause of the following exception:\n\nTraceback (most recent call last):\n  File "/app/bazarr/bin/bazarr/../libs/urllib3/connectionpool.py", line 789, in urlopen\n    response = self._make_request(\n               ^^^^^^^^^^^^^^^^^^^\n  File "/app/bazarr/bin/bazarr/../libs/urllib3/connectionpool.py", line 490, in _make_request\n    raise new_e\n  File "/app/bazarr/bin/bazarr/../libs/urllib3/connectionpool.py", line 466, in _make_request\n    self._validate_conn(conn)\n  File "/app/bazarr/bin/bazarr/../libs/urllib3/connectionpool.py", line 1095, in _validate_conn\n    conn.connect()\n  File "/app/bazarr/bin/bazarr/../libs/urllib3/connection.py", line 693, in connect\n    self.sock = sock = self._new_conn()\n                       ^^^^^^^^^^^^^^^^\n  File "/app/bazarr/bin/bazarr/../libs/urllib3/connection.py", line 206, in _new_conn\n    raise NameResolutionError(self.host, self, e) from e\nurllib3.exceptions.NameResolutionError: <urllib3.connection.HTTPSConnection object at 0xffff821534d0>: Failed to resolve \'raw.githubusercontent.com\' ([Errno -3] Try again)\n\nThe above exception was the direct cause of the following exception:\n\nTraceback (most recent call last):\n  File "/app/bazarr/bin/bazarr/../libs/requests/adapters.py", line 667, in send\n    resp = conn.urlopen(\n           ^^^^^^^^^^^^^\n  File "/app/bazarr/bin/bazarr/../libs/urllib3/connectionpool.py", line 843, in urlopen\n    retries = retries.increment(\n              ^^^^^^^^^^^^^^^^^^\n  File "/app/bazarr/bin/bazarr/../libs/urllib3/util/retry.py", line 519, in increment\n    raise MaxRetryError(_pool, url, reason) from reason  # type: ignore[arg-type]\n    ^^^^^^^^^^^^^^^^^^^^^^^^^^^^^^^^^^^^^^^^^^^^^^^^^^^\nurllib3.exceptions.MaxRetryError: HTTPSConnectionPool(host=\'raw.githubusercontent.com\', port=443): Max retries exceeded with url: /morpheus65535/bazarr-binaries/master/announcements.json (Caused by NameResolutionError("<urllib3.connection.HTTPSConnection object at 0xffff821534d0>: Failed to resolve \'raw.githubusercontent.com\' ([Errno -3] Try again)"))\n\nDuring handling of the above exception, another exception occurred:\n\nTraceback (most recent call last):\n  File "/app/bazarr/bin/bazarr/app/announcements.py", line 53, in get_announcements_to_file\n    r = requests.get("https://raw.githubusercontent.com/morpheus65535/bazarr-binaries/master/announcements.json",\n        ^^^^^^^^^^^^^^^^^^^^^^^^^^^^^^^^^^^^^^^^^^^^^^^^^^^^^^^^^^^^^^^^^^^^^^^^^^^^^^^^^^^^^^^^^^^^^^^^^^^^^^^^^\n  File "/app/bazarr/bin/bazarr/../libs/requests/api.py", line 73, in get\n    return request("get", url, params=params, **kwargs)\n           ^^^^^^^^^^^^^^^^^^^^^^^^^^^^^^^^^^^^^^^^^^^^\n  File "/app/bazarr/bin/bazarr/../libs/requests/api.py", line 59, in request\n    return session.request(method=method, url=url, **kwargs)\n           ^^^^^^^^^^^^^^^^^^^^^^^^^^^^^^^^^^^^^^^^^^^^^^^^^\n  File "/app/bazarr/bin/bazarr/../libs/requests/sessions.py", line 589, in request\n    resp = self.send(prep, **send_kwargs)\n           ^^^^^^^^^^^^^^^^^^^^^^^^^^^^^^\n  File "/app/bazarr/bin/bazarr/../libs/requests/sessions.py", line 703, in send\n    r = adapter.send(request, **kwargs)\n        ^^^^^^^^^^^^^^^^^^^^^^^^^^^^^^^\n  File "/app/bazarr/bin/bazarr/../libs/requests/adapters.py", line 700, in send\n    raise ConnectionError(e, request=request)\nrequests.exceptions.ConnectionError: HTTPSConnectionPool(host=\'raw.githubusercontent.com\', port=443): Max retries exceeded with url: /morpheus65535/bazarr-binaries/master/announcements.json (Caused by NameResolutionError("<urllib3.connection.HTTPSConnection object at 0xffff821534d0>: Failed to resolve \'raw.githubusercontent.com\' ([Errno -3] Try again)"))'|
2025-09-01 08:43:24|ERROR   |root                            |Error trying to get releases from Github. Connection Error.|'Traceback (most recent call last):\n  File "/app/bazarr/bin/bazarr/../libs/urllib3/connection.py", line 199, in _new_conn\n    sock = connection.create_connection(\n           ^^^^^^^^^^^^^^^^^^^^^^^^^^^^^\n  File "/app/bazarr/bin/bazarr/../custom_libs/subliminal_patch/http.py", line 325, in patched_create_connection\n    return _orig_create_connection(address, *args, **kwargs)\n           ^^^^^^^^^^^^^^^^^^^^^^^^^^^^^^^^^^^^^^^^^^^^^^^^^\n  File "/app/bazarr/bin/bazarr/../libs/urllib3/util/connection.py", line 60, in create_connection\n    for res in socket.getaddrinfo(host, port, family, socket.SOCK_STREAM):\n               ^^^^^^^^^^^^^^^^^^^^^^^^^^^^^^^^^^^^^^^^^^^^^^^^^^^^^^^^^^\n  File "/usr/lib/python3.12/socket.py", line 978, in getaddrinfo\n    for res in _socket.getaddrinfo(host, port, family, type, proto, flags):\n               ^^^^^^^^^^^^^^^^^^^^^^^^^^^^^^^^^^^^^^^^^^^^^^^^^^^^^^^^^^^\nsocket.gaierror: [Errno -3] Try again\n\nThe above exception was the direct cause of the following exception:\n\nTraceback (most recent call last):\n  File "/app/bazarr/bin/bazarr/../libs/urllib3/connectionpool.py", line 789, in urlopen\n    response = self._make_request(\n               ^^^^^^^^^^^^^^^^^^^\n  File "/app/bazarr/bin/bazarr/../libs/urllib3/connectionpool.py", line 490, in _make_request\n    raise new_e\n  File "/app/bazarr/bin/bazarr/../libs/urllib3/connectionpool.py", line 466, in _make_request\n    self._validate_conn(conn)\n  File "/app/bazarr/bin/bazarr/../libs/urllib3/connectionpool.py", line 1095, in _validate_conn\n    conn.connect()\n  File "/app/bazarr/bin/bazarr/../libs/urllib3/connection.py", line 693, in connect\n    self.sock = sock = self._new_conn()\n                       ^^^^^^^^^^^^^^^^\n  File "/app/bazarr/bin/bazarr/../libs/urllib3/connection.py", line 206, in _new_conn\n    raise NameResolutionError(self.host, self, e) from e\nurllib3.exceptions.NameResolutionError: <urllib3.connection.HTTPSConnection object at 0xffff81d17fb0>: Failed to resolve \'api.github.com\' ([Errno -3] Try again)\n\nThe above exception was the direct cause of the following exception:\n\nTraceback (most recent call last):\n  File "/app/bazarr/bin/bazarr/../libs/requests/adapters.py", line 667, in send\n    resp = conn.urlopen(\n           ^^^^^^^^^^^^^\n  File "/app/bazarr/bin/bazarr/../libs/urllib3/connectionpool.py", line 843, in urlopen\n    retries = retries.increment(\n              ^^^^^^^^^^^^^^^^^^\n  File "/app/bazarr/bin/bazarr/../libs/urllib3/util/retry.py", line 519, in increment\n    raise MaxRetryError(_pool, url, reason) from reason  # type: ignore[arg-type]\n    ^^^^^^^^^^^^^^^^^^^^^^^^^^^^^^^^^^^^^^^^^^^^^^^^^^^\nurllib3.exceptions.MaxRetryError: HTTPSConnectionPool(host=\'api.github.com\', port=443): Max retries exceeded with url: /repos/morpheus65535/Bazarr/releases?per_page=100 (Caused by NameResolutionError("<urllib3.connection.HTTPSConnection object at 0xffff81d17fb0>: Failed to resolve \'api.github.com\' ([Errno -3] Try again)"))\n\nDuring handling of the above exception, another exception occurred:\n\nTraceback (most recent call last):\n  File "/app/bazarr/bin/bazarr/app/check_update.py", line 28, in check_releases\n    r = requests.get(url_releases, allow_redirects=True, timeout=15)\n        ^^^^^^^^^^^^^^^^^^^^^^^^^^^^^^^^^^^^^^^^^^^^^^^^^^^^^^^^^^^^\n  File "/app/bazarr/bin/bazarr/../libs/requests/api.py", line 73, in get\n    return request("get", url, params=params, **kwargs)\n           ^^^^^^^^^^^^^^^^^^^^^^^^^^^^^^^^^^^^^^^^^^^^\n  File "/app/bazarr/bin/bazarr/../libs/requests/api.py", line 59, in request\n    return session.request(method=method, url=url, **kwargs)\n           ^^^^^^^^^^^^^^^^^^^^^^^^^^^^^^^^^^^^^^^^^^^^^^^^^\n  File "/app/bazarr/bin/bazarr/../libs/requests/sessions.py", line 589, in request\n    resp = self.send(prep, **send_kwargs)\n           ^^^^^^^^^^^^^^^^^^^^^^^^^^^^^^\n  File "/app/bazarr/bin/bazarr/../libs/requests/sessions.py", line 703, in send\n    r = adapter.send(request, **kwargs)\n        ^^^^^^^^^^^^^^^^^^^^^^^^^^^^^^^\n  File "/app/bazarr/bin/bazarr/../libs/requests/adapters.py", line 700, in send\n    raise ConnectionError(e, request=request)\nrequests.exceptions.ConnectionError: HTTPSConnectionPool(host=\'api.github.com\', port=443): Max retries exceeded with url: /repos/morpheus65535/Bazarr/releases?per_page=100 (Caused by NameResolutionError("<urllib3.connection.HTTPSConnection object at 0xffff81d17fb0>: Failed to resolve \'api.github.com\' ([Errno -3] Try again)"))'|
2025-09-01 08:43:41|INFO    |root                            |BAZARR Finished searching for missing Series Subtitles. Check History for more information.|
2025-09-01 09:00:02|INFO    |root                            |BAZARR Finished searching for missing Movies Subtitles. Check History for more information.|
2025-09-01 11:52:20|ERROR   |root                            |BAZARR SignalR client for Radarr connection as been lost. Trying to reconnect...|
2025-09-01 11:52:23|ERROR   |root                            |BAZARR SignalR client for Sonarr connection as been lost. Trying to reconnect...|
2025-09-01 12:01:05|INFO    |root                            |Scheduler will use this timezone: Asia/Jerusalem|
2025-09-01 12:01:06|INFO    |root                            |BAZARR trying to connect to Sonarr SignalR feed...|
2025-09-01 12:01:06|INFO    |root                            |BAZARR trying to connect to Radarr SignalR feed...|
2025-09-01 12:01:06|INFO    |waitress                        |BAZARR is started and waiting for requests on: http://***.***.***.***:6767|
2025-09-01 12:01:06|INFO    |waitress                        |BAZARR is started and waiting for requests on: http://[::]:6767|
2025-09-01 12:01:06|INFO    |root                            |BAZARR SignalR client for Sonarr is connected and waiting for events.|
2025-09-01 12:01:26|INFO    |root                            |BAZARR SignalR client for Radarr is connected and waiting for events.|
2025-09-01 12:53:02|ERROR   |root                            |BAZARR SignalR client for Sonarr connection as been lost. Trying to reconnect...|
2025-09-01 12:53:03|ERROR   |root                            |BAZARR SignalR client for Radarr connection as been lost. Trying to reconnect...|
2025-09-01 14:37:30|INFO    |root                            |Scheduler will use this timezone: Asia/Jerusalem|
2025-09-01 14:37:40|INFO    |root                            |BAZARR trying to connect to Sonarr SignalR feed...|
2025-09-01 14:37:40|INFO    |root                            |BAZARR trying to connect to Radarr SignalR feed...|
2025-09-01 14:37:40|INFO    |waitress                        |BAZARR is started and waiting for requests on: http://***.***.***.***:6767|
2025-09-01 14:37:40|INFO    |waitress                        |BAZARR is started and waiting for requests on: http://[::]:6767|
2025-09-01 14:37:40|INFO    |root                            |BAZARR SignalR client for Radarr is connected and waiting for events.|
2025-09-01 14:37:40|INFO    |root                            |BAZARR SignalR client for Sonarr is connected and waiting for events.|
2025-09-01 20:11:59|INFO    |root                            |BAZARR Finished searching for missing Series Subtitles. Check History for more information.|
2025-09-01 20:30:32|INFO    |root                            |BAZARR Finished searching for missing Movies Subtitles. Check History for more information.|
2025-09-01 20:47:55|ERROR   |root                            |BAZARR SignalR client for Sonarr connection as been lost. Trying to reconnect...|
